[2020-01-30 07:04:47.678030] [*] Languages data recompiled.
[2020-01-30 07:04:50.723313] [*] progracat bot started. - v2.3.0
[2020-02-04 03:06:43.224088] [*] Languages data recompiled.
[2020-02-04 03:06:46.424449] [*] progracat bot started. - v2.3.1
[2020-02-05 03:06:45.277753] [*] Languages data recompiled.
[2020-02-05 06:46:20.866192] [*] Process started. timeout:30s
[2020-02-05 06:46:20.905714] [+] Program exited. 
[2020-02-05 06:49:24.010038] [*] Languages data recompiled. (state=1)
[2020-02-06 03:06:48.956978] [*] Languages data recompiled.
[2020-02-07 03:06:50.998263] [*] Languages data recompiled.
[2020-02-07 03:33:44.062532] [*] Languages data recompiled.
[2020-02-07 03:33:47.072431] [*] progracat bot started. - v2.3.1
Fatal error on SSL transport
protocol: <asyncio.sslproto.SSLProtocol object at 0x74f92970>
transport: <_SelectorSocketTransport closing fd=7 read=idle write=<idle, bufsize=0>>
Traceback (most recent call last):
  File "/usr/lib/python3.5/asyncio/sslproto.py", line 635, in _process_write_backlog
    self._on_handshake_complete)
  File "/usr/lib/python3.5/asyncio/sslproto.py", line 135, in do_handshake
    ssldata, appdata = self.feed_ssldata(b'', only_handshake=True)
  File "/usr/lib/python3.5/asyncio/sslproto.py", line 201, in feed_ssldata
    self._sslobj.do_handshake()
  File "/usr/lib/python3.5/ssl.py", line 641, in do_handshake
    self._sslobj.do_handshake()
ssl.SSLError: getrandom() initialization failed. (_ssl.c:720)
Fatal error on SSL transport
protocol: <asyncio.sslproto.SSLProtocol object at 0x74f92990>
transport: <_SelectorSocketTransport closing fd=7 read=idle write=<idle, bufsize=0>>
Traceback (most recent call last):
  File "/usr/lib/python3.5/asyncio/sslproto.py", line 635, in _process_write_backlog
    self._on_handshake_complete)
  File "/usr/lib/python3.5/asyncio/sslproto.py", line 135, in do_handshake
    ssldata, appdata = self.feed_ssldata(b'', only_handshake=True)
  File "/usr/lib/python3.5/asyncio/sslproto.py", line 201, in feed_ssldata
    self._sslobj.do_handshake()
  File "/usr/lib/python3.5/ssl.py", line 641, in do_handshake
    self._sslobj.do_handshake()
ssl.SSLError: getrandom() initialization failed. (_ssl.c:720)
Fatal error on SSL transport
protocol: <asyncio.sslproto.SSLProtocol object at 0x74f92c30>
transport: <_SelectorSocketTransport closing fd=7 read=idle write=<idle, bufsize=0>>
Traceback (most recent call last):
  File "/usr/lib/python3.5/asyncio/sslproto.py", line 635, in _process_write_backlog
    self._on_handshake_complete)
  File "/usr/lib/python3.5/asyncio/sslproto.py", line 135, in do_handshake
    ssldata, appdata = self.feed_ssldata(b'', only_handshake=True)
  File "/usr/lib/python3.5/asyncio/sslproto.py", line 201, in feed_ssldata
    self._sslobj.do_handshake()
  File "/usr/lib/python3.5/ssl.py", line 641, in do_handshake
    self._sslobj.do_handshake()
ssl.SSLError: getrandom() initialization failed. (_ssl.c:720)
Fatal error on SSL transport
protocol: <asyncio.sslproto.SSLProtocol object at 0x74f92cb0>
transport: <_SelectorSocketTransport closing fd=7 read=idle write=<idle, bufsize=0>>
Traceback (most recent call last):
  File "/usr/lib/python3.5/asyncio/sslproto.py", line 635, in _process_write_backlog
    self._on_handshake_complete)
  File "/usr/lib/python3.5/asyncio/sslproto.py", line 135, in do_handshake
    ssldata, appdata = self.feed_ssldata(b'', only_handshake=True)
  File "/usr/lib/python3.5/asyncio/sslproto.py", line 201, in feed_ssldata
    self._sslobj.do_handshake()
  File "/usr/lib/python3.5/ssl.py", line 641, in do_handshake
    self._sslobj.do_handshake()
ssl.SSLError: getrandom() initialization failed. (_ssl.c:720)
Fatal error on SSL transport
protocol: <asyncio.sslproto.SSLProtocol object at 0x74f92df0>
transport: <_SelectorSocketTransport closing fd=7 read=idle write=<idle, bufsize=0>>
Traceback (most recent call last):
  File "/usr/lib/python3.5/asyncio/sslproto.py", line 635, in _process_write_backlog
    self._on_handshake_complete)
  File "/usr/lib/python3.5/asyncio/sslproto.py", line 135, in do_handshake
    ssldata, appdata = self.feed_ssldata(b'', only_handshake=True)
  File "/usr/lib/python3.5/asyncio/sslproto.py", line 201, in feed_ssldata
    self._sslobj.do_handshake()
  File "/usr/lib/python3.5/ssl.py", line 641, in do_handshake
    self._sslobj.do_handshake()
ssl.SSLError: getrandom() initialization failed. (_ssl.c:720)
[2020-02-07 03:37:10.268038] [*] Languages data recompiled.
Traceback (most recent call last):
  File "/home/pi/.local/lib/python3.5/site-packages/aiohttp/connector.py", line 924, in _wrap_create_connection
    await self._loop.create_connection(*args, **kwargs))
  File "/usr/lib/python3.5/asyncio/base_events.py", line 801, in create_connection
    sock, protocol_factory, ssl, server_hostname)
  File "/usr/lib/python3.5/asyncio/base_events.py", line 827, in _create_connection_transport
    yield from waiter
  File "/usr/lib/python3.5/asyncio/futures.py", line 380, in __iter__
    yield self  # This tells Task to wait for completion.
  File "/usr/lib/python3.5/asyncio/tasks.py", line 304, in _wakeup
    future.result()
  File "/usr/lib/python3.5/asyncio/futures.py", line 293, in result
    raise self._exception
  File "/usr/lib/python3.5/asyncio/sslproto.py", line 635, in _process_write_backlog
    self._on_handshake_complete)
  File "/usr/lib/python3.5/asyncio/sslproto.py", line 135, in do_handshake
    ssldata, appdata = self.feed_ssldata(b'', only_handshake=True)
  File "/usr/lib/python3.5/asyncio/sslproto.py", line 201, in feed_ssldata
    self._sslobj.do_handshake()
  File "/usr/lib/python3.5/ssl.py", line 641, in do_handshake
    self._sslobj.do_handshake()
ssl.SSLError: getrandom() initialization failed. (_ssl.c:720)

The above exception was the direct cause of the following exception:

Traceback (most recent call last):
  File "progracat.py", line 75, in <module>
    bot.run(TOKEN)
  File "/home/pi/.local/lib/python3.5/site-packages/discord/client.py", line 598, in run
    return future.result()
  File "/usr/lib/python3.5/asyncio/futures.py", line 293, in result
    raise self._exception
  File "/usr/lib/python3.5/asyncio/tasks.py", line 241, in _step
    result = coro.throw(exc)
  File "/home/pi/.local/lib/python3.5/site-packages/discord/client.py", line 579, in runner
    await self.start(*args, **kwargs)
  File "/home/pi/.local/lib/python3.5/site-packages/discord/client.py", line 542, in start
    await self.login(*args, bot=bot)
  File "/home/pi/.local/lib/python3.5/site-packages/discord/client.py", line 400, in login
    await self.http.static_login(token, bot=bot)
  File "/home/pi/.local/lib/python3.5/site-packages/discord/http.py", line 258, in static_login
    data = await self.request(Route('GET', '/users/@me'))
  File "/home/pi/.local/lib/python3.5/site-packages/discord/http.py", line 158, in request
    async with self.__session.request(method, url, **kwargs) as r:
  File "/home/pi/.local/lib/python3.5/site-packages/aiohttp/client.py", line 1005, in __aenter__
    self._resp = await self._coro
  File "/home/pi/.local/lib/python3.5/site-packages/aiohttp/client.py", line 476, in _request
    timeout=real_timeout
  File "/home/pi/.local/lib/python3.5/site-packages/aiohttp/connector.py", line 522, in connect
    proto = await self._create_connection(req, traces, timeout)
  File "/home/pi/.local/lib/python3.5/site-packages/aiohttp/connector.py", line 854, in _create_connection
    req, traces, timeout)
  File "/home/pi/.local/lib/python3.5/site-packages/aiohttp/connector.py", line 992, in _create_direct_connection
    raise last_exc
  File "/home/pi/.local/lib/python3.5/site-packages/aiohttp/connector.py", line 974, in _create_direct_connection
    req=req, client_error=client_error)
  File "/home/pi/.local/lib/python3.5/site-packages/aiohttp/connector.py", line 929, in _wrap_create_connection
    raise ClientConnectorSSLError(req.connection_key, exc) from exc
aiohttp.client_exceptions.ClientConnectorSSLError: Cannot connect to host discordapp.com:443 ssl:None [getrandom() initialization failed. (_ssl.c:720)]
[2020-02-07 03:39:06.663746] [*] Languages data recompiled.
[2020-02-07 03:39:09.668655] [*] progracat bot started. - v2.3.1
[2020-02-07 03:51:53.750344] [*] Languages data recompiled. (state=3)
[2020-02-07 03:52:11.478386] [*] Languages data recompiled. (state=2)
[2020-02-08 03:39:08.889419] [*] Languages data recompiled.
[2020-02-09 03:39:11.036210] [*] Languages data recompiled.
[2020-02-09 11:26:56.123830] [*] Languages data recompiled. (state=1)
[2020-02-09 15:11:56.560590] [*] Languages data recompiled.
[2020-02-09 15:11:59.648089] [*] progracat bot started. - v2.3.1
[2020-02-10 13:56:06.059228] [*] Languages data recompiled.
[2020-02-10 13:56:09.233054] [*] progracat bot started. - v2.4.0
[2020-02-10 17:06:27.965898] [*] Languages data recompiled.
[2020-02-10 17:06:31.116549] [*] progracat bot started. - v2.4.0
[2020-02-10 14:13:18.734003] [*] Languages data recompiled.
[2020-02-10 14:13:21.916317] [*] progracat bot started. - v2.4.0
Traceback (most recent call last):
  File "progracat.py", line 75, in <module>
    bot.run(TOKEN)
  File "/home/pi/.local/lib/python3.5/site-packages/discord/client.py", line 595, in run
    _cleanup_loop(loop)
  File "/home/pi/.local/lib/python3.5/site-packages/discord/client.py", line 92, in _cleanup_loop
    _cancel_tasks(loop)
  File "/home/pi/.local/lib/python3.5/site-packages/discord/client.py", line 77, in _cancel_tasks
    loop.run_until_complete(asyncio.gather(*tasks, loop=loop, return_exceptions=True))
  File "/usr/lib/python3.5/asyncio/base_events.py", line 464, in run_until_complete
    raise RuntimeError('Event loop stopped before Future completed.')
RuntimeError: Event loop stopped before Future completed.
Traceback (most recent call last):
  File "progracat.py", line 75, in <module>
    bot.run(TOKEN)
  File "/home/pi/.local/lib/python3.5/site-packages/discord/client.py", line 595, in run
    _cleanup_loop(loop)
  File "/home/pi/.local/lib/python3.5/site-packages/discord/client.py", line 92, in _cleanup_loop
    _cancel_tasks(loop)
  File "/home/pi/.local/lib/python3.5/site-packages/discord/client.py", line 77, in _cancel_tasks
    loop.run_until_complete(asyncio.gather(*tasks, loop=loop, return_exceptions=True))
  File "/usr/lib/python3.5/asyncio/base_events.py", line 464, in run_until_complete
    raise RuntimeError('Event loop stopped before Future completed.')
RuntimeError: Event loop stopped before Future completed.
[2020-02-10 17:06:45.345388] [*] Languages data recompiled.
[2020-02-10 17:06:48.361367] [*] progracat bot started. - v2.4.0
[2020-02-11 04:21:19.082344] [*] Languages data recompiled.
[2020-02-11 04:21:22.122047] [*] progracat bot started. - v2.4.0
[2020-02-11 10:51:00.479222] [*] Languages data recompiled.
[2020-02-11 10:51:03.539724] [*] progracat bot started. - v2.4.0
[2020-02-11 10:53:00.783414] [*] Languages data recompiled.
[2020-02-11 10:53:03.812282] [*] progracat bot started. - v2.4.0
[2020-02-12 10:53:04.677451] [*] Languages data recompiled.
[2020-02-12 12:45:01.401776] [*] Languages data recompiled.
[2020-02-12 12:45:09.608247] [*] progracat bot started. - v2.4.0
[2020-02-13 12:45:03.811167] [*] Languages data recompiled.
[2020-02-14 06:13:05.603676] [*] Languages data recompiled.
[2020-02-14 06:13:08.643889] [*] progracat bot started. - v2.4.0
[2020-02-14 06:28:43.664645] [*] Languages data recompiled.
[2020-02-14 06:28:46.746640] [*] progracat bot started. - v2.4.0
[2020-02-14 06:30:53.343405] [*] Languages data recompiled.
[2020-02-14 06:30:56.357983] [*] progracat bot started. - v2.4.0
